Workbook
Name age: #REF!
Name count: #REF!
Name FromArray_1: _xlfn.ANCHORARRAY(PivotTables!$E$117)
Name Slicer_Month: #N/A
Name Slicer_Subcategory: #N/A
Name worth: #REF!

Sheet Dashboard
U1: =IFERROR(GETPIVOTDATA("Sum of Amount",PivotTables!$B$22,"Cash Flow","Income"),0) -> 466700 | V1: =IFERROR(GETPIVOTDATA("Sum of Amount",PivotTables!$B$22,"Cash Flow","Income"),0) -> 466700
U2: =IFERROR(GETPIVOTDATA("Sum of Amount",PivotTables!$B$22,"Cash Flow","Expense"),0) -> 396351 | V2: =IFERROR(GETPIVOTDATA("Sum of Amount",PivotTables!$B$22,"Cash Flow","Expense"),0) -> 396351
U3: =IFERROR(GETPIVOTDATA("Sum of Amount",PivotTables!$B$22,"Cash Flow","Income"),0)-IFERROR(GETPIVOTDATA("Sum of Amount",PivotTables!$B$22,"Cash Flow","Expense"),0) -> 70349 | V3: =IFERROR(GETPIVOTDATA("Sum of Amount",PivotTables!$B$22,"Cash Flow","Income"),0)-IFERROR(GETPIVOTDATA("Sum of Amount",PivotTables!$B$22,"Cash Flow","Expense"),0) -> 70349
U5: {=_xlfn.IFS( PivotTables!E103>0,"Expenses are below budget, showing controlled essential spending.", PivotTables!E103<0,"Expenses exceeded the budget and may require review.", PivotTables!E103=0,"Expenses matched the budget exactly." )} -> Expenses are below budget, showing controlled essential spending.
U6: {=_xlfn.IFS( PivotTables!E102>0,"The value is above the target, showing a positive result.", PivotTables!E102<0,"The value is below the target, showing a negative result.", PivotTables!E102=0,"The value met the target exactly." )} -> The value is above the target, showing a positive result.
U7: {=_xlfn.IFS( PivotTables!E104>0,"You stayed within your budget, leaving more room for savings or essentials.", PivotTables!E104<0,"You spent more than planned on wants like dining out, shopping, or entertainment Etc.", PivotTables!E104=0,"Your wants spending is exactly aligned with your budget." )} -> You spent more than planned on wants like dining out, shopping, or entertainment Etc.
U9: =PivotTables!F115 -> Apr
U10: =PivotTables!G115 -> 48480
U11: =PivotTables!I115
U13: =PivotTables!H40 -> 0.23464051
U14: =PivotTables!I40 -> 93000
U15: ="of expenses spent on "&PivotTables!G40 -> of expenses spent on Rent / Mortgage
V17: =PivotTables!H85 -> 17500
U18: =PivotTables!G85 -> May | V18: =PivotTables!H86 -> 10000
U19: =PivotTables!G86 -> Jan
V20: =PivotTables!H69 -> 12250
U21: =PivotTables!G69 -> Jul | V21: =PivotTables!H70 -> 2392.5789
U22: =PivotTables!G70 -> Dec
V23: =PivotTables!H55 -> 7000
U24: =PivotTables!G55 -> Jan | V24: =PivotTables!H56 -> 250
U25: =PivotTables!G56 -> Apr

Sheet PivotTables
B3: Amount of Cash Flows by Month | C3: Expense | G3: =IFERROR(VLOOKUP(C1,$B$5:$C$14,2,FALSE()),"")
B4: Row Labels | C4: Expense | D4: Income | E4: Grand Total
B5: Apr | C5: 48480 | D5: 49200 | E5: 97680
B6: May | C6: 50226 | D6: 50000 | E6: 100226
B7: Jun | C7: 44191 | D7: 50000 | E7: 94191
B8: Jul | C8: 40959 | D8: 49000 | E8: 89959
B9: Aug | C9: 40459 | D9: 49000 | E9: 89459
B10: Sep | C10: 37459 | D10: 49000 | E10: 86459
B11: Oct | C11: 37659 | D11: 49000 | E11: 86659
B12: Nov | C12: 41459 | D12: 49000 | E12: 90459
B13: Dec | C13: 45459 | D13: 49000 | E13: 94459
B14: Jan | C14: 10000 | D14: 23500 | E14: 33500
B15: Grand Total | C15: 396351 | D15: 466700 | E15: 863051
B16: Balance | C16: =(SUM(D15-C15)/D15) -> 0.15073709 | D16: =1-C16 -> 0.84926291
B20: Month | C20: (All)
B22: Total Income/Expenses | C22: Sum of Amount
B23: Expense | C23: 396351 | D23: =GETPIVOTDATA("Sum of Amount",$B$22,"Cash Flow","Expense") -> 396351
B24: Income | C24: 466700 | D24: =GETPIVOTDATA("Sum of Amount",$B$22,"Cash Flow","Income") -> 466700
B25: Grand Total | C25: 863051
B26: Balance | C26: =C24-C23 -> 70349 | D26: =C26/C24 -> 0.15073709 | E26: =1-D26 -> 0.84926291
B27: Percent | C27: =C23/C24 -> 0.84926291 | D27: =IFERROR(C23/C24, "") -> 0.84926291
C28: =1-C27 -> 0.15073709
B31: Percentage by SubCategory | C31: Count of Subcategory | D31: Sum of Amount
B32: Financial Priority | C32: 0.38139535 | D32: 261681 | E32: =C32 -> 0.38139535 | F32: =1-E32 -> 0.61860465
B33: Needs | C33: 0.40930233 | D33: 109500 | E33: =C33 -> 0.40930233 | F33: =1-C33 -> 0.59069767
B34: Salary | C34: 0.17674419 | D34: 466700
B35: Wants | C35: 0.03255814 | D35: 25170 | E35: =C35 -> 0.03255814 | F35: =1-E35 -> 0.96744186
B36: Grand Total | C36: 1 | D36: 863051
B40: Total by Category | C40: Sum of Amount | E40: Total by Category | F40: Sum of Amount | G40: =E41 -> Rent / Mortgage | H40: =F41/C23 -> 0.23464051 | I40: =F41 -> 93000
B41: Car Maintenance | C41: 6000 | E41: Rent / Mortgage | F41: 93000
B42: School | C42: 7500 | E42: Groceries | F42: 81500
B43: Fuel | C43: 10000 | E43: Car Payment | F43: 74550
B44: Public Transport | C44: 10500 | E44: Loan | F44: 59168
B45: Other Expenses | C45: 25170 | E45: Utilities | F45: 28963
B46: Utilities | C46: 28963 | E46: Other Expenses | F46: 25170
B47: Loan | C47: 59168 | E47: Public Transport | F47: 10500
B48: Car Payment | C48: 74550 | E48: Fuel | F48: 10000
B49: Groceries | C49: 81500 | E49: School | F49: 7500
B50: Rent / Mortgage | C50: 93000 | E50: Car Maintenance | F50: 6000
B51: Grand Total | C51: 396351 | E51: Grand Total | F51: 396351
...

Sheet Transactions END
B2: Date | C2: Month | D2: Cash Flow | E2: Category | F2: Amount | G2: Actual | H2: Subcategory | I2: Description (optional) | K2: Type | L2: Cash Flow | M2: Sub Type
B3: 46127 | C3: =TEXT(B3,"mmm") -> Apr | D3: =_xlfn.XLOOKUP(Table1[[#This Row],[Category]],Table2[Type],Table2[Cash Flow]) -> Income | E3: Dave Salary | F3: 16500 | G3: 17500 | H3: =_xlfn.XLOOKUP(Table1[[#This Row],[Category]],Table2[Type],Table2[Sub Type]) -> Salary | I3: Monthly salary | K3: Dave Salary | L3: Income | M3: Salary
B4: 46127 | C4: =TEXT(B4,"mmm") -> Apr | D4: =_xlfn.XLOOKUP(Table1[[#This Row],[Category]],Table2[Type],Table2[Cash Flow]) -> Income | E4: Cath Salary | F4: 8000 | G4: 8000 | H4: =_xlfn.XLOOKUP(Table1[[#This Row],[Category]],Table2[Type],Table2[Sub Type]) -> Salary | I4: Monthly salary | K4: Cath Salary | L4: Income | M4: Salary
B5: 46128 | C5: =TEXT(B5,"mmm") -> Apr | D5: =_xlfn.XLOOKUP(Table1[[#This Row],[Category]],Table2[Type],Table2[Cash Flow]) -> Expense | E5: Car Payment | F5: 1500 | G5: 1500 | H5: =_xlfn.XLOOKUP(Table1[[#This Row],[Category]],Table2[Type],Table2[Sub Type]) -> Financial Priority | I5: for March payment | K5: Interest / Dividends | L5: Income | M5: Additional
B6: 46128 | C6: =TEXT(B6,"mmm") -> Apr | D6: =_xlfn.XLOOKUP(Table1[[#This Row],[Category]],Table2[Type],Table2[Cash Flow]) -> Expense | E6: Rent / Mortgage | F6: 7000 | G6: 7000 | H6: =_xlfn.XLOOKUP(Table1[[#This Row],[Category]],Table2[Type],Table2[Sub Type]) -> Financial Priority | I6: House | K6: Gifts / Other | L6: Income | M6: Additional
B7: 46128 | C7: =TEXT(B7,"mmm") -> Apr | D7: =_xlfn.XLOOKUP(Table1[[#This Row],[Category]],Table2[Type],Table2[Cash Flow]) -> Expense | E7: Utilities | F7: 300 | G7: 300 | H7: =_xlfn.XLOOKUP(Table1[[#This Row],[Category]],Table2[Type],Table2[Sub Type]) -> Financial Priority | I7: Internet | K7: Rent / Mortgage | L7: Expense | M7: Financial Priority
B8: 46128 | C8: =TEXT(B8,"mmm") -> Apr | D8: =_xlfn.XLOOKUP(Table1[[#This Row],[Category]],Table2[Type],Table2[Cash Flow]) -> Expense | E8: Groceries | F8: 1000 | G8: 1000 | H8: =_xlfn.XLOOKUP(Table1[[#This Row],[Category]],Table2[Type],Table2[Sub Type]) -> Needs | I8: Milk | K8: Utilities | L8: Expense | M8: Financial Priority
B9: 46128 | C9: =TEXT(B9,"mmm") -> Apr | D9: =_xlfn.XLOOKUP(Table1[[#This Row],[Category]],Table2[Type],Table2[Cash Flow]) -> Expense | E9: Utilities | F9: 500 | G9: 500 | H9: =_xlfn.XLOOKUP(Table1[[#This Row],[Category]],Table2[Type],Table2[Sub Type]) -> Financial Priority | I9: Water | K9: Property Tax | L9: Expense | M9: Financial Priority
B10: 46128 | C10: =TEXT(B10,"mmm") -> Apr | D10: =_xlfn.XLOOKUP(Table1[[#This Row],[Category]],Table2[Type],Table2[Cash Flow]) -> Expense | E10: Loan | F10: 1060 | G10: 1060 | H10: =_xlfn.XLOOKUP(Table1[[#This Row],[Category]],Table2[Type],Table2[Sub Type]) -> Financial Priority | I10: Atome | K10: Household Goods | L10: Expense | M10: Needs
B11: 46128 | C11: =TEXT(B11,"mmm") -> Apr | D11: =_xlfn.XLOOKUP(Table1[[#This Row],[Category]],Table2[Type],Table2[Cash Flow]) -> Expense | E11: Groceries | F11: 2500 | G11: 2500 | H11: =_xlfn.XLOOKUP(Table1[[#This Row],[Category]],Table2[Type],Table2[Sub Type]) -> Needs | I11: Food | K11: Car Payment | L11: Expense | M11: Financial Priority
B12: 46128 | C12: =TEXT(B12,"mmm") -> Apr | D12: =_xlfn.XLOOKUP(Table1[[#This Row],[Category]],Table2[Type],Table2[Cash Flow]) -> Expense | E12: Public Transport | F12: 2000 | G12: 2000 | H12: =_xlfn.XLOOKUP(Table1[[#This Row],[Category]],Table2[Type],Table2[Sub Type]) -> Needs | I12: Cath transpo | K12: Fuel | L12: Expense | M12: Needs
B13: 46128 | C13: =TEXT(B13,"mmm") -> Apr | D13: =_xlfn.XLOOKUP(Table1[[#This Row],[Category]],Table2[Type],Table2[Cash Flow]) -> Expense | E13: Other Expenses | F13: 2670 | G13: 2670 | H13: =_xlfn.XLOOKUP(Table1[[#This Row],[Category]],Table2[Type],Table2[Sub Type]) -> Wants | I13: Parcel and lalamove and Proj. | K13: Public Transport | L13: Expense | M13: Needs
B14: 46128 | C14: =TEXT(B14,"mmm") -> Apr | D14: =_xlfn.XLOOKUP(Table1[[#This Row],[Category]],Table2[Type],Table2[Cash Flow]) -> Expense | E14: Loan | F14: 1000 | G14: 1000 | H14: =_xlfn.XLOOKUP(Table1[[#This Row],[Category]],Table2[Type],Table2[Sub Type]) -> Financial Priority | I14: Yhella | K14: Taxis & Other | L14: Expense | M14: Wants
... B17: 46128 | C17: =TEXT(B17,"mmm") -> Apr | D17: =_xlfn.XLOOKUP(Table1[[#This Row],[Category]],Table2[Type],Table2[Cash Flow]) -> Expense | E17: Loan | F17: 3470 | G17: 3470 | H17: =_xlfn.XLOOKUP(Table1[[#This Row],[Category]],Table2[Type],Table2[Sub Type]) -> Financial Priority | I17: unkown | K17: Medical Expenses | L17: Expense | M17: Needs
B18: 46142 | C18: =TEXT(B18,"mmm") -> Apr | D18: =_xlfn.XLOOKUP(Table1[[#This Row],[Category]],Table2[Type],Table2[Cash Flow]) -> Income | E18: Dave Salary | F18: 17000 | H18: =_xlfn.XLOOKUP(Table1[[#This Row],[Category]],Table2[Type],Table2[Sub Type]) -> Salary | K18: Supplements | L18: Expense | M18: Needs
B19: 46142 | C19: =TEXT(B19,"mmm") -> Apr | D19: =_xlfn.XLOOKUP(Table1[[#This Row],[Category]],Table2[Type],Table2[Cash Flow]) -> Income | E19: Cath Salary | F19: 7700 | H19: =_xlfn.XLOOKUP(Table1[[#This Row],[Category]],Table2[Type],Table2[Sub Type]) -> Salary | K19: Groceries | L19: Expense | M19: Needs
B20: 46142 | C20: =TEXT(B20,"mmm") -> Apr | D20: =_xlfn.XLOOKUP(Table1[[#This Row],[Category]],Table2[Type],Table2[Cash Flow]) -> Expense | E20: Loan | F20: 4000 | G20: 4000 | H20: =_xlfn.XLOOKUP(Table1[[#This Row],[Category]],Table2[Type],Table2[Sub Type]) -> Financial Priority | I20: mama | K20: Eating Out | L20: Expense | M20: Wants
B21: 46142 | C21: =TEXT(B21,"mmm") -> Apr | D21: =_xlfn.XLOOKUP(Table1[[#This Row],[Category]],Table2[Type],Table2[Cash Flow]) -> Expense | E21: Car Payment | F21: 8500 | G21: 8500 | H21: =_xlfn.XLOOKUP(Table1[[#This Row],[Category]],Table2[Type],Table2[Sub Type]) -> Financial Priority | I21: for March payment | K21: Entertainment | L21: Expense | M21: Wants
B22: 46142 | C22: =TEXT(B22,"mmm") -> Apr | D22: =_xlfn.XLOOKUP(Table1[[#This Row],[Category]],Table2[Type],Table2[Cash Flow]) -> Expense | E22: Loan | F22: 3460 | G22: 3460 | H22: =_xlfn.XLOOKUP(Table1[[#This Row],[Category]],Table2[Type],Table2[Sub Type]) -> Financial Priority | I22: ate for april | K22: Travel | L22: Expense | M22: Wants
B23: 46142 | C23: =TEXT(B23,"mmm") -> Apr | D23: =_xlfn.XLOOKUP(Table1[[#This Row],[Category]],Table2[Type],Table2[Cash Flow]) -> Expense | E23: Groceries | F23: 2500 | G23: 2500 | H23: =_xlfn.XLOOKUP(Table1[[#This Row],[Category]],Table2[Type],Table2[Sub Type]) -> Needs | I23: food | K23: Other Expenses | L23: Expense | M23: Wants
B24: 46142 | C24: =TEXT(B24,"mmm") -> Apr | D24: =_xlfn.XLOOKUP(Table1[[#This Row],[Category]],Table2[Type],Table2[Cash Flow]) -> Expense | E24: Groceries | F24: 1200 | G24: 1200 | H24: =_xlfn.XLOOKUP(Table1[[#This Row],[Category]],Table2[Type],Table2[Sub Type]) -> Needs | I24: Milk | K24: Loan | L24: Expense | M24: Financial Priority
B25: 46142 | C25: =TEXT(B25,"mmm") -> Apr | D25: =_xlfn.XLOOKUP(Table1[[#This Row],[Category]],Table2[Type],Table2[Cash Flow]) -> Expense | E25: Groceries | F25: 500 | G25: 500 | H25: =_xlfn.XLOOKUP(Table1[[#This Row],[Category]],Table2[Type],Table2[Sub Type]) -> Needs | I25: Diaper | K25: School | L25: Expense | M25: Needs
B26: 46142 | C26: =TEXT(B26,"mmm") -> Apr | D26: =_xlfn.XLOOKUP(Table1[[#This Row],[Category]],Table2[Type],Table2[Cash Flow]) -> Expense | E26: Utilities | F26: 1300 | G26: 1300 | H26: =_xlfn.XLOOKUP(Table1[[#This Row],[Category]],Table2[Type],Table2[Sub Type]) -> Financial Priority | I26: Kuryente | K26: Credit Card | L26: Expense | M26: Needs
B27: 46142 | C27: =TEXT(B27,"mmm") -> Apr | D27: =_xlfn.XLOOKUP(Table1[[#This Row],[Category]],Table2[Type],Table2[Cash Flow]) -> Expense | E27: Public Transport | F27: 1000 | G27: 1000 | H27: =_xlfn.XLOOKUP(Table1[[#This Row],[Category]],Table2[Type],Table2[Sub Type]) -> Needs | I27: Cath pamasahe sa trece | K27: Savings | L27: Savings | M27: Financial Priority
B28: 46142 | C28: =TEXT(B28,"mmm") -> Apr | D28: =_xlfn.XLOOKUP(Table1[[#This Row],[Category]],Table2[Type],Table2[Cash Flow]) -> Expense | E28: Utilities | F28: 250 | G28: 250 | H28: =_xlfn.XLOOKUP(Table1[[#This Row],[Category]],Table2[Type],Table2[Sub Type]) -> Financial Priority | I28: Internet
B29: 46142 | C29: =TEXT(B29,"mmm") -> Apr | D29: =_xlfn.XLOOKUP(Table1[[#This Row],[Category]],Table2[Type],Table2[Cash Flow]) -> Expense | E29: Loan | F29: 1000 | G29: 1000 | H29: =_xlfn.XLOOKUP(Table1[[#This Row],[Category]],Table2[Type],Table2[Sub Type]) -> Financial Priority | I29: Atome
B30: 46142 | C30: =TEXT(B30,"mmm") -> Apr | D30: =_xlfn.XLOOKUP(Table1[[#This Row],[Category]],Table2[Type],Table2[Cash Flow]) -> Expense | E30: Utilities | F30: 270 | G30: 270 | H30: =_xlfn.XLOOKUP(Table1[[#This Row],[Category]],Table2[Type],Table2[Sub Type]) -> Financial Priority | I30: Water
B31: 46157 | C31: =TEXT(B31,"mmm") -> May | D31: =_xlfn.XLOOKUP(Table1[[#This Row],[Category]],Table2[Type],Table2[Cash Flow]) -> Income | E31: Dave Salary | F31: 16500 | H31: =_xlfn.XLOOKUP(Table1[[#This Row],[Category]],Table2[Type],Table2[Sub Type]) -> Salary
B32: 46157 | C32: =TEXT(B32,"mmm") -> May | D32: =_xlfn.XLOOKUP(Table1[[#This Row],[Category]],Table2[Type],Table2[Cash Flow]) -> Income | E32: Cath Salary | F32: 8000 | H32: =_xlfn.XLOOKUP(Table1[[#This Row],[Category]],Table2[Type],Table2[Sub Type]) -> Salary
B33: 46157 | C33: =TEXT(B33,"mmm") -> May | D33: =_xlfn.XLOOKUP(Table1[[#This Row],[Category]],Table2[Type],Table2[Cash Flow]) -> Expense | E33: Rent / Mortgage | F33: 9000 | G33: 9000 | H33: =_xlfn.XLOOKUP(Table1[[#This Row],[Category]],Table2[Type],Table2[Sub Type]) -> Financial Priority | I33: House
B34: 46157 | C34: =TEXT(B34,"mmm") -> May | D34: =_xlfn.XLOOKUP(Table1[[#This Row],[Category]],Table2[Type],Table2[Cash Flow]) -> Expense | E34: Utilities | F34: 250 | G34: 250 | H34: =_xlfn.XLOOKUP(Table1[[#This Row],[Category]],Table2[Type],Table2[Sub Type]) -> Financial Priority | I34: Internet
B35: 46157 | C35: =TEXT(B35,"mmm") -> May | D35: =_xlfn.XLOOKUP(Table1[[#This Row],[Category]],Table2[Type],Table2[Cash Flow]) -> Expense | E35: Groceries | F35: 1500 | G35: 1489 | H35: =_xlfn.XLOOKUP(Table1[[#This Row],[Category]],Table2[Type],Table2[Sub Type]) -> Needs | I35: Milk
B36: 46157 | C36: =TEXT(B36,"mmm") -> May | D36: =_xlfn.XLOOKUP(Table1[[#This Row],[Category]],Table2[Type],Table2[Cash Flow]) -> Expense | E36: Utilities | F36: 1300 | G36: 1950 | H36: =_xlfn.XLOOKUP(Table1[[#This Row],[Category]],Table2[Type],Table2[Sub Type]) -> Financial Priority | I36: Kuryente
B37: 46157 | C37: =TEXT(B37,"mmm") -> May | D37: =_xlfn.XLOOKUP(Table1[[#This Row],[Category]],Table2[Type],Table2[Cash Flow]) -> Expense | E37: Public Transport | F37: 500 | G37: 200 | H37: =_xlfn.XLOOKUP(Table1[[#This Row],[Category]],Table2[Type],Table2[Sub Type]) -> Needs | I37: cath pamasahe sa trece
B38: 46157 | C38: =TEXT(B38,"mmm") -> May | D38: =_xlfn.XLOOKUP(Table1[[#This Row],[Category]],Table2[Type],Table2[Cash Flow]) -> Expense | E38: Groceries | F38: 2500 | G38: 3500 | H38: =_xlfn.XLOOKUP(Table1[[#This Row],[Category]],Table2[Type],Table2[Sub Type]) -> Needs | I38: Food
B39: 46157 | C39: =TEXT(B39,"mmm") -> May | D39: =_xlfn.XLOOKUP(Table1[[#This Row],[Category]],Table2[Type],Table2[Cash Flow]) -> Expense | E39: Groceries | F39: 500 | G39: 100 | H39: =_xlfn.XLOOKUP(Table1[[#This Row],[Category]],Table2[Type],Table2[Sub Type]) -> Needs | I39: Diaper
B40: 46157 | C40: =TEXT(B40,"mmm") -> May | D40: =_xlfn.XLOOKUP(Table1[[#This Row],[Category]],Table2[Type],Table2[Cash Flow]) -> Expense | E40: Loan | F40: 1166 | G40: 1166 | H40: =_xlfn.XLOOKUP(Table1[[#This Row],[Category]],Table2[Type],Table2[Sub Type]) -> Financial Priority | I40: Atome Cash
B41: 46157 | C41: =TEXT(B41,"mmm") -> May | D41: =_xlfn.XLOOKUP(Table1[[#This Row],[Category]],Table2[Type],Table2[Cash Flow]) -> Expense | E41: Groceries | F41: 500 | G41: 0 | H41: =_xlfn.XLOOKUP(Table1[[#This Row],[Category]],Table2[Type],Table2[Sub Type]) -> Needs | I41: Toiletries
B42: 46157 | C42: =TEXT(B42,"mmm") -> May | D42: =_xlfn.XLOOKUP(Table1[[#This Row],[Category]],Table2[Type],Table2[Cash Flow]) -> Expense | E42: Other Expenses | F42: 4500 | G42: 6000 | H42: =_xlfn.XLOOKUP(Table1[[#This Row],[Category]],Table2[Type],Table2[Sub Type]) -> Wants | I42: Macey bday
B43: 46157 | C43: =TEXT(B43,"mmm") -> May | D43: =_xlfn.XLOOKUP(Table1[[#This Row],[Category]],Table2[Type],Table2[Cash Flow]) -> Expense | E43: Fuel | F43: 1000 | G43: 1000 | H43: =_xlfn.XLOOKUP(Table1[[#This Row],[Category]],Table2[Type],Table2[Sub Type]) -> Needs | I43: Fuel
...

Sheet Quotes
A1: "Do the best you can until you know better. Then when you know better, do better." — Maya Angelou, Poet & Author | B1: {=INDEX(A1:A29,RANDBETWEEN(1,COUNTA(A1:A29)))} -> "When I dare to be powerful, to use my strength in the service of my vision, then it becomes less and less important whether I am afraid." — Audre Lorde, Poet & Civil Rights Activist
A2: "We must be impatient for change. Let us remember that our voice is a precious gift and we must use it." — Claudia Flores, Clinical Professor of Law at Yale Law School | B2: )
A3: "The only way you really see change, is by helping create it." — Lena Waithe, Emmy Award-Winning Writer & Producer
A4: "Do not allow people to dim your shine because they are blinded. Tell them to put on some sunglasses, because we were born this way." — Lady Gaga
A5: "Purpose is the essential element of you. It is the reason you are on the planet at this particular time in history." — Chadwick Boseman, Actor & Activist
A6: "The most difficult thing is the decision to act, the rest is merely tenacity." — Amelia Earhart, Aviation Pioneer
A7: "Ditch the dream and be a doer, not a dreamer." — Shonda Rhimes, Television Producer & Writer
A8: "Start where you are. Use what you have. Do what you can." — Arthur Ashe, Tennis Champion & Activist
A9: "What you do makes a difference, and you have to decide what kind of difference you want to make." — Jane Goodall, Primatologist & Conservationist
A10: "You have to write the book that wants to be written. And if the book will be too difficult for grown-ups, then you write it for children." — Madeleine L'Engle, Author
A11: "Courage is found in unlikely places." — Gildor Inglorion (character from The Lord of the Rings by J.R.R. Tolkien)
A12: "The most important step a person can take is always the next one." — Dalinar Kholin (character from The Stormlight Archive by Brandon Sanderson)
A13: "When I dare to be powerful, to use my strength in the service of my vision, then it becomes less and less important whether I am afraid." — Audre Lorde, Poet & Civil Rights Activist
A14: "A journey of a thousand li begins at one's feet." — Lao Tzu (Laozi), Ancient Chinese Philosopher
... A29: "You're braver than you believe, stronger than you seem, and smarter than you think." — Christopher Robin (character from Pooh's Grand Adventure)
